<?xml version="1.0"?>
<robot name="carro">

  <!-- colors -->
 
  <material name="red">
    <color rgba="1 0 0 1"/>
  </material>

  <material name="black">
    <color rgba="0 0 0 1"/>
  </material>

  <material name="white">
    <color rgba="1 1 1 1"/>
  </material>

  <!-- links -->

  <link name="base_link">
    <visual>
      <geometry>
        <box size="0.4 0.8 0.2"/>
      </geometry>
      <material name="red"/>
    </visual>
    <collision>
      <geometry> 
        <box size="0.4 0.8 0.2"/>
      </geometry>
    </collision>
    <inertial>
      <mass value="10"/>
      <inertia ixx="0.1" ixy="0.0" ixz="0.0" iyy="0.1" iyz="0.0" izz="0.1" />
    </inertial>
  </link>

  <link name="right_front_wheel">
    <visual>
      <origin rpy="1.57075 0 1.57075" xyz="0 0 0"/>
      <geometry>
        <cylinder length="0.05" radius="0.1"/>
      </geometry>
      <material name="black"/>
    </visual>
    <collision>
      <origin rpy="1.57075 0 1.57075" xyz="0 0 0"/>
      <geometry>
        <cylinder length="0.05" radius="0.1"/>
      </geometry>
    </collision>
    <inertial>
      <mass value="4"/>
      <inertia ixx="0.1" ixy="0.0" ixz="0.0" iyy="0.1" iyz="0.0" izz="0.1"/>
    </inertial>
  </link>

  <link name="left_front_wheel">
    <visual>
      <origin rpy="1.57075 0 1.57075" xyz="0 0 0"/>
      <geometry>
        <cylinder length="0.05" radius="0.1"/>
      </geometry>
      <material name="black"/>
    </visual>
    <collision>
      <origin rpy="1.57075 0 1.57075" xyz="0 0 0"/>
      <geometry>
        <cylinder length="0.05" radius="0.1"/>
      </geometry>
    </collision>
    <inertial>
      <mass value="4"/>
      <inertia ixx="0.1" ixy="0.0" ixz="0.0" iyy="0.1" iyz="0.0" izz="0.1"/>
    </inertial>
  </link>

  <link name="right_back_wheel">
    <visual>
      <origin rpy="1.57075 0 1.57075" xyz="0 0 0"/>
      <geometry>
        <cylinder length="0.05" radius="0.1"/>
      </geometry>
      <material name="black"/>
    </visual>
    <collision>
      <origin rpy="1.57075 0 1.57075" xyz="0 0 0"/>
      <geometry>
        <cylinder length="0.05" radius="0.1"/>
      </geometry>
    </collision>
    <inertial>
      <mass value="4"/>
      <inertia ixx="0.1" ixy="0.0" ixz="0.0" iyy="0.1" iyz="0.0" izz="0.1"/>
    </inertial>
  </link>

  <link name="left_back_wheel">
    <visual>
      <origin rpy="1.57075 0 1.57075" xyz="0 0 0"/>
      <geometry>
        <cylinder length="0.05" radius="0.1"/>
      </geometry>
      <material name="black"/>
    </visual>
    <collision>
      <origin rpy="1.57075 0 1.57075" xyz="0 0 0"/>
      <geometry>
        <cylinder length="0.05" radius="0.1"/>
      </geometry>
    </collision>
    <inertial>
      <mass value="4"/>
      <inertia ixx="0.1" ixy="0.0" ixz="0.0" iyy="0.1" iyz="0.0" izz="0.1"/>
    </inertial>
  </link>

  <link name="center_sphere">
    <visual>
      <geometry>
        <sphere radius="0.1"/>
      </geometry>
      <material name="white"/>
    </visual>
    <collision>
      <geometry>
        <sphere radius="0.1"/>
      </geometry>
    </collision>
    <inertial>
      <mass value="4"/>
      <inertia ixx="0.1" ixy="0.0" ixz="0.0" iyy="0.1" iyz="0.0" izz="0.1"/>
    </inertial>
  </link>

  <link name="top">
    <visual>
      <geometry>
        <box size="0.35 0.2 0.2"/>
      </geometry>
      <material name="red"/>
    </visual>
    <collision>
      <geometry>
        <box size="0.35 0.2 0.2"/>
      </geometry>
    </collision>
    <inertial>
      <mass value="1"/>
      <inertia ixx="0.1" ixy="0.0" ixz="0.0" iyy="0.1" iyz="0.0" izz="0.1"/>
    </inertial>
  </link>

  <link name="mirror">
    <visual>
      <geometry>
        <box size="0.25 0.05 0.15"/>
      </geometry>
      <material name="white"/>
    </visual>
    <collision>
      <geometry>
        <box size="0.25 0.05 0.15"/>
      </geometry>
    </collision>
    <inertial>
      <mass value="1"/>
      <inertia ixx="0.1" ixy="0.0" ixz="0.0" iyy="0.1" iyz="0.0" izz="0.1"/>
    </inertial>
  </link>

  <link name="front">
    <visual>
      <geometry>
        <box size="0.3 0.05 0.15"/>
      </geometry>
      <material name="red"/>
    </visual>
    <collision>
      <geometry>
        <box size="0.3 0.05 0.15"/>
      </geometry>
    </collision>
    <inertial>
      <mass value="1"/>
      <inertia ixx="0.1" ixy="0.0" ixz="0.0" iyy="0.1" iyz="0.0" izz="0.1"/>
    </inertial>
  </link>

  <link name="back">
    <visual>
      <geometry>
        <box size="0.3 0.05 0.15"/>
      </geometry>
      <material name="red"/>
    </visual>
    <collision>
      <geometry>
        <box size="0.3 0.05 0.15"/>
      </geometry>
    </collision>
    <inertial>
      <mass value="1"/>
      <inertia ixx="0.1" ixy="0.0" ixz="0.0" iyy="0.1" iyz="0.0" izz="0.1"/>
    </inertial>
  </link>

  <!-- joints -->

  <joint name="right_front_wheel_joint" type="continuous">
    <axis rpy="0 0 0" xyz="-1 0 0"/>
    <parent link="base_link"/>
    <child link="right_front_wheel"/>
    <origin rpy="0 0 0" xyz="0.22 0.2 -0.1"/>
    <limit effort="10000" velocity="1000"/>
    <joint_properties damping="1.0" friction="1.0"/>
  </joint>

  <joint name="left_front_wheel_joint" type="continuous">
    <axis rpy="0 0 0" xyz="-1 0 0"/>
    <parent link="base_link"/>
    <child link="left_front_wheel"/>
    <origin rpy="0 0 0" xyz="-0.22 0.2 -0.1"/>
    <limit effort="10000" velocity="1000"/>
    <joint_properties damping="1.0" friction="1.0"/>
  </joint>

  <joint name="right_back_wheel_joint" type="continuous">
    <axis rpy="0 0 0" xyz="-1 0 0"/>
    <parent link="base_link"/>
    <child link="right_back_wheel"/>
    <origin rpy="0 0 0" xyz="0.22 -0.2 -0.1"/>
    <limit effort="10000" velocity="1000"/>
    <joint_properties damping="1.0" friction="1.0"/>
  </joint>

  <joint name="left_back_wheel_joint" type="continuous">
    <axis rpy="0 0 0" xyz="-1 0 0"/>
    <parent link="base_link"/>
    <child link="left_back_wheel"/>
    <origin rpy="0 0 0" xyz="-0.22 -0.2 -0.1"/>
    <limit effort="10000" velocity="1000"/>
    <joint_properties damping="1.0" friction="1.0"/>
  </joint>

  <joint name="center_sphere_joint" type="continuous">
    <axis rpy="0 0 0" xyz="0 0 1"/>
    <parent link="base_link"/>
    <child link="center_sphere"/>
    <origin rpy="0 0 0" xyz="0 0 -0.1"/>
  </joint>

  <joint name="top_joint" type="fixed">
    <parent link="base_link"/>
    <child link="top"/>
    <origin rpy="0 0 0" xyz="0 0.2 0.12"/>
  </joint>

  <joint name="mirror_joint" type="fixed">
    <parent link="base_link"/>
    <child link="mirror"/>
    <origin rpy="0 0 0" xyz="0 0.3 0.12"/>
  </joint>

  <joint name="front_joint" type="fixed">
    <parent link="base_link"/>
    <child link="front"/>
    <origin rpy="0 0 0" xyz="0 0.4 0"/>
  </joint>

  <joint name="back_joint" type="fixed">
    <parent link="base_link"/>
    <child link="back"/>
    <origin rpy="0 0 0" xyz="0 -0.4 0"/>
  </joint>

  <!-- transmissions -->

  <transmission name="right_front_wheel_transmission">
    <type>transmission_interface/SimpleTransmission</type>
    <joint name="right_front_wheel_joint">
      <hardwareInterface>hardware_interface/PositionJointInterface</hardwareInterface>
    </joint>
    <actuator name="right_front_wheel_actuator">
        <hardwareInterface>hardware_interface/PositionJointInterface</hardwareInterface>
      <mechanicalReduction>1</mechanicalReduction>
    </actuator>    
  </transmission>

  <transmission name="left_front_wheel_transmission">
    <type>transmission_interface/SimpleTransmission</type>
    <joint name="left_front_wheel_joint">
      <hardwareInterface>hardware_interface/PositionJointInterface</hardwareInterface>
    </joint>
    <actuator name="left_front_wheel_actuator">
        <hardwareInterface>hardware_interface/PositionJointInterface</hardwareInterface>
      <mechanicalReduction>1</mechanicalReduction>
    </actuator>    
  </transmission>

  <transmission name="right_back_wheel_transmission">
    <type>transmission_interface/SimpleTransmission</type>
    <joint name="right_back_wheel_joint">
      <hardwareInterface>hardware_interface/PositionJointInterface</hardwareInterface>
    </joint>
    <actuator name="right_back_wheel_actuator">
        <hardwareInterface>hardware_interface/PositionJointInterface</hardwareInterface>
      <mechanicalReduction>1</mechanicalReduction>
    </actuator>    
  </transmission>

  <transmission name="left_back_wheel_transmission">
    <type>transmission_interface/SimpleTransmission</type>
    <joint name="left_back_wheel_joint">
      <hardwareInterface>hardware_interface/PositionJointInterface</hardwareInterface>
    </joint>
    <actuator name="left_back_wheel_actuator">
        <hardwareInterface>hardware_interface/PositionJointInterface</hardwareInterface>
      <mechanicalReduction>1</mechanicalReduction>
    </actuator>    
  </transmission>  

  <!-- colors for gazebo -->

  <gazebo reference="base_link">
    <material>Gazebo/Red</material>
  </gazebo>

  <gazebo reference="top">
    <material>Gazebo/Red</material>
  </gazebo>

  <gazebo reference="front">
    <material>Gazebo/Red</material>
  </gazebo>

  <gazebo reference="back">
    <material>Gazebo/Red</material>
  </gazebo>

  <gazebo reference="mirror">
    <material>Gazebo/White</material>
  </gazebo>

  <gazebo reference="center_sphere">
    <material>Gazebo/White</material>
  </gazebo>

  <gazebo reference="right_front_wheel">
    <material>Gazebo/Black</material>
  </gazebo>

  <gazebo reference="left_front_wheel">
    <material>Gazebo/Black</material>
  </gazebo>

  <gazebo reference="right_back_wheel">
    <material>Gazebo/Black</material>
  </gazebo>

  <gazebo reference="left_back_wheel">
    <material>Gazebo/Black</material>
  </gazebo>
 
  <!-- gazebo plugins -->

  <gazebo>
    <plugin name="gazebo_ros_control" filename="libgazebo_ros_control.so">
      <robotNamespace>/carro</robotNamespace>
    </plugin>

    <plugin name="skid_steer_drive_controller" filename="libgazebo_ros_skid_steer_drive.so">
      <updateRate>100.0</updateRate>
      <robotNamespace>/carro</robotNamespace>
      <leftFrontJoint>left_front_wheel_joint</leftFrontJoint>
      <rightFrontJoint>right_front_wheel_joint</rightFrontJoint>
      <leftRearJoint>left_back_wheel_joint</leftRearJoint>
      <rightRearJoint>right_back_wheel_joint</rightRearJoint>
      <wheelSeparation>0.4</wheelSeparation>
      <wheelDiameter>0.2</wheelDiameter>
      <robotBaseFrame>base_link</robotBaseFrame>
      <torque>20</torque>
      <topicName>cmd_vel</topicName>
      <broadcastTF>false</broadcastTF>
    </plugin>
  </gazebo>

</robot>